<?xml version="1.0"?>
<robot name="origins">
    <material name="blue">
        <color rgba="0 0 1 0.2"/>
    </material>
    <material name="red">
        <color rgba="1 0 0 0.2"/>
    </material>
    
    <link name="arm1">
        <visual>
            <geometry>
                <cylinder length="1" radius="0.1" />
            </geometry>
            <origin xyz="0 -0.5 0" rpy="1.5708 0.0 0.0 "/>
            <material name="blue"/>
        </visual>
       <inertial>
  	     <mass value="10"/>
  	     <inertia ixx="0.0" ixy="0.0" ixz="0.0" iyy="0.0" iyz="0.0" izz="0.0"/>
       </inertial>
    </link>

    <link name="arm2">
        <visual>
            <geometry>
                <cylinder length="1" radius="0.1" />
            </geometry>
            <origin xyz="0 0.5 0"  rpy="1.5708 0.0 0.0"/>
            <material name="red"/>
        </visual>
       <inertial>
  	     <mass value="10"/>
  	     <inertia ixx="0.0" ixy="0.0" ixz="0.0" iyy="0.0" iyz="0.0" izz="0.0"/>
       </inertial>
    </link>

    <joint name="arm_to_arm" type="revolute">
        <axis xyz="1 0 0"/>
        <origin xyz="0 0 0"/>
        <limit effort="1000.0" lower="0.0" upper="2.617" velocity="0.5"/>
        <parent link="arm1" />
        <child link="arm2"/>
    </joint>

    <link name="palm">
        <visual>
            <geometry>
                <box size="0.1 0.5 0.4" />
            </geometry>
            <origin xyz="0 0.25 0"/>
            <material name="blue"/>
        </visual>

       <inertial>
  	     <mass value="10"/>
  	     <inertia ixx="0.0" ixy="0.0" ixz="0.0" iyy="0.0" iyz="0.0" izz="0.0"/>
       </inertial>
    </link>

    <joint name="arm_to_palm" type="revolute">
        <axis xyz="0 1 0"/>
        <origin xyz="0 1 0" rpy="1.1 1 1.25"/>
        <limit effort="1000.0" lower="0" upper="9" velocity="0.01"/>
        <parent link="arm2" />
        <child link="palm"/>
    </joint>

    <link name="thumb">
        <visual>
            <geometry>
                <box size="0.1 0.1 0.4" />
            </geometry>
            <origin xyz="0 0.0 0.2"/>
            <material name="red"/>
        </visual>

       <inertial>
  	     <mass value="10"/>
  	     <inertia ixx="0.0" ixy="0.0" ixz="0.0" iyy="0.0" iyz="0.0" izz="0.0"/>
       </inertial>
    </link>

    <joint name="palm_to_thumb" type="revolute">
        <axis xyz="0 -1 0"/>
        <origin xyz="0 0.25 0.2"/>
        <limit effort="1000.0" lower="0.0" upper="1.57075" velocity="0.5"/>
        <parent link="palm" />
        <child link="thumb"/>
    </joint>

    <link name="finger_1">
        <visual>
            <geometry>
                <box size="0.1 0.4 0.1" />
            </geometry>
            <origin xyz="0 0.2 0.0"/>
            <material name="red"/>
        </visual>
       <inertial>
  	     <mass value="10"/>
  	     <inertia ixx="0.0" ixy="0.0" ixz="0.0" iyy="0.0" iyz="0.0" izz="0.0"/>
       </inertial>
    </link>

    <joint name="palm_to_finger_1" type="revolute">
        <axis xyz="0 0 1"/>
        <origin xyz="0 0.5 0.1"/>
        <limit effort="1000.0" lower="0.0" upper="1.57075" velocity="0.5"/>
        <parent link="palm" />
        <child link="finger_1"/>
    </joint>

    <link name="finger_2">
        <visual>
            <geometry>
                <box size="0.1 0.4 0.1" />
            </geometry>
            <origin xyz="0 0.2 0.0"/>
            <material name="red"/>
        </visual>
       <inertial>
  	     <mass value="10"/>
  	     <inertia ixx="0.0" ixy="0.0" ixz="0.0" iyy="0.0" iyz="0.0" izz="0.0"/>
       </inertial>
    </link>

    <joint name="palm_to_finger_2" type="revolute">
        <axis xyz="0 0 1"/>
        <origin xyz="0 0.5 -0.1"/>
        <limit effort="1000.0" lower="0.0" upper="1.57075" velocity="0.5"/>
        <parent link="palm" />
        <child link="finger_2"/>
    </joint>

</robot>